<?xml version="1.0"?>
<robot xmlns:xacro="http://www.ros.org/wiki/xacro"  >

<xacro:include filename="inertial_macros.xacro"/>

        <material name="white">
        <color rgba="1 1 1 1"/>
        </material>

         <material name="orange">
        <color rgba="1 0.3 0.1 1"/>
        </material>

         <material name="blue">
        <color rgba="0.2 0.2 1 1"/>
        </material>

         <material name="black">
        <color rgba="0 0 0 1"/>
        </material>

        <!--BASE LINK-->

        <link name="base_link">

        </link>

        <joint name="chassis_joint" type="fixed">
            <parent link="base_link"/>
            <child link="chassis"/>
            <origin xyz="-0.1 0 0"/>
        </joint>

         <!--Chassis LINK  jak bedziesz zmieniał wymiary to w kolizji tez trzeba zmienic-->
        <link name="chassis">
            <visual>
                <origin xyz="0 0 0.055"/>
                <geometry>
                    <box size = "0.24 0.232 0.055"/>
                </geometry>
                <material name="white"/>
            </visual>
              <collision>
                <origin xyz="0 0 0.055"/>
                <geometry>
                    <box size = "0.24 0.232 0.055"/>
                </geometry>
            </collision>
            <xacro:inertial_box mass="0.5" x="0.24" y="0.232" z="0.055">
                <origin xyz="0 0 0.055" rpy="0 0 0"/>
            </xacro:inertial_box>

        </link>

         <!--lewe przednie koło-->
         <joint name="left_front_wheel_joint" type="continuous">
            <parent link="base_link"/>
            <child link="left_front_wheel"/>
            <origin xyz="-0.05 0.116 0" rpy="-${pi/2} 0 0"/>
            <axis xyz="0 0 1"/>

         </joint>

          <link name="left_front_wheel">
            <visual>
                
                <geometry>
                    <cylinder radius= "0.0325" length="0.027"/>
                </geometry>
                <material name="blue"/>
            </visual>
            <collision>
                <geometry>
                    <cylinder radius= "0.0325" length="0.027"/>
                </geometry>
            </collision>
            <xacro:inertial_cylinder mass="0.1" length="0.027" radius="0.0325">
                <origin xyz="0 0 0" rpy="0 0 0"/>
            </xacro:inertial_cylinder>
        </link>


         <!--lewe tylnie koło-->
         <joint name="left_back_wheel_joint" type="continuous">
            <parent link="base_link"/>
            <child link="left_back_wheel"/>
            <origin xyz="-0.15 0.116 0" rpy="-${pi/2} 0 0"/>
            <axis xyz="0 0 1"/>
            
         </joint>

          <link name="left_back_wheel">
            <visual>
                
                <geometry>
                    <cylinder radius= "0.0325" length="0.027"/>
                </geometry>
                <material name="blue"/>
            </visual>
             <collision>
                <geometry>
                    <cylinder radius= "0.0325" length="0.027"/>
                </geometry>
            </collision>
            <xacro:inertial_cylinder mass="0.1" length="0.027" radius="0.0325">
                <origin xyz="0 0 0" rpy="0 0 0"/>
            </xacro:inertial_cylinder>
        </link>

        <!--prawe przednie koło-->
         <joint name="right_front_wheel_joint" type="continuous">
            <parent link="base_link"/>
            <child link="right_front_wheel"/>
            <origin xyz="-0.05 -0.116 0" rpy="${pi/2} 0 0"/>
            <axis xyz="0 0 -1"/>

         </joint>

          <link name="right_front_wheel">
            <visual>
                
                <geometry>
                    <cylinder radius= "0.0325" length="0.027"/>
                </geometry>
                <material name="blue"/>
            </visual>
              <collision>
                
                <geometry>
                    <cylinder radius= "0.0325" length="0.027"/>
                </geometry>
                <material name="blue"/>
            </collision>
            <xacro:inertial_cylinder mass="0.1" length="0.027" radius="0.0325">
                <origin xyz="0 0 0" rpy="0 0 0"/>
            </xacro:inertial_cylinder>
        </link>

  <!--prawe tylnie koło-->
         <joint name="right_back_wheel_joint" type="continuous">
            <parent link="base_link"/>
            <child link="right_back_wheel"/>
            <origin xyz="-0.15 -0.116 0" rpy="${pi/2} 0 0"/>
            <axis xyz="0 0 -1"/>
            
         </joint>

          <link name="right_back_wheel">
            <visual>
                
                <geometry>
                    <cylinder radius= "0.0325" length="0.027"/>
                </geometry>
                <material name="blue"/>
            </visual>
               <collision>
                <geometry>
                    <cylinder radius= "0.0325" length="0.027"/>
                </geometry>
            </collision>
            <xacro:inertial_cylinder mass="0.1" length="0.027" radius="0.0325">
                <origin xyz="0 0 0" rpy="0 0 0"/>
            </xacro:inertial_cylinder>
        </link>

</robot>